# 본문의 글은 인프런 앨런 Swift문법 마스터 스쿨(온라인) 부트캠프의 강의 영상을 본후 공부한 내용을 정리하여 기록한것입니다.
https://inf.run/YyoR

```swift
//에러를 던지는 함수를 처리하는 함수 ============================

//에러 정의
enum SomeError: Error {
    case aError
}

//에러를 던지는 함수 정의 (무조건 에러를 던진다고 가정)
func throwingFunc() throws {
    throw SomeError.aError
}

//에러의 처리

do {
    try throwingFunc()
} catch {
    print(error)
}


//일반적인 함수로 처리
//함수 내부에서 do-catchㅁㄴ으로 에러를 처리
//즉 , 발생한 에러를 catch블럭에서 받아서 알맞은 처리

func handleError() {
    do {
        try throwingFunc()
    } catch {
        print(error)
    }
}

handleError()





//throwing함수로 에러 다시 던지기
//함수내에서 에러를 직접처리하지못하는경우 에러를 한번더 다시 던질수 있음
func handleError1() throws { //throws 키워드를 사용해 한번 더 던지기
        try throwingFunc() //do-catch블럭이 없어도 에러를 밖으로 던질수 있음
}

do { //에러를 받아서 처리
    try handleError1()
} catch {
    print(error)
}




//rethrowing 함수로 에러 다시던지기 (rethrows 키워드)
//에러를 다시 던지는 throwing함수를 "파라미터로 받는경우", 내부에서 다시 에러던지기가 가능
//rethrow키워드 필요(Rethrowing메서드)


//다시 에러를 던지는 함수(방법1)
func someFunction1(callback: () throws -> Void) rethrows { //에러를 던질수있는 함수를 파라미터로 받고 실행할때 다시 에러를 던질수있게해주는 키워드
    try callback()        //에러를 다시 던짐(직접던지지는 못함)기 때문에 do-catch문을 생략가능
}

do {
    try someFunction1(callback: throwingFunc)
} catch {
    print(error)
}

//다시 에러를 던지는 함수(방법2) - 에러변환
func someFunction2(callback: () throws -> Void) rethrows { //에러를 던질수있는 함수를 파라미터로 받고 실행할때 다시 에러를 던질수있게해주는 키워드
    enum ChangedError: Error { //새로운 에러 열거형을 만들고
        case cError
    }
    do {
        try callback()
    } catch {
        throw ChangedError.cError //고냥 변환 시켜주는것 뿐
    }
}

do {
    try someFunction2(callback: throwingFunc)
} catch {
    print(error)
}







//메서드/생성자 =================================
//에러는 Throwing함수 뿐만 아니라, 메서드와 생성자에도 적용이 가능하다
//에러를 던질수 있는 메서드는 Throwing 메서드, 에러를 던질수있는 생성자는 Throwing 생성자

//에러정의
enum NameError: Error {
    case noName
}


//생성자와 메서드에도 적용이 가능
class Course {
    var name: String
    
    init(name: String) throws { //에러를 발생시킬수 있는 함수라는 키워드인 throws
        if name == "" {
            throw NameError.noName
        } else {
            self.name = name
            print("수업을 올바르게 생성")
        }
    }
}

//에러 처리

do {
    _ = try Course(name: "") //에러처리할때는 곡 try
} catch NameError.noName {
    print("이름없는에러")
}



//생성자와 메서드의 재정의 =============================

class NewCourse: Course {
    
    override init(name: String) throws { //에러를 발생시킬수 있는 함수라는 키워드인 throws
        try super.init(name: name)  //에러처리할때는 곡 try
    }
}


/*
 - Throwing 메서드/생성자는 재정의할 때, 반드시 Throwing메서드/생성자로 재정의해야함
   (Throwing 메서드/생성자를 일반 메서드/생성자로 재정의 불가)

 - 일반 메서드/생성자를 Throwing 메서드/생성자로 재정의 하는 것은 가능
   (일반 메서드/생성자의 범위가 더 큼)
 
 [상속관계에서]
 - (상위) throws함수    (하위) throws함수재정의    (O 가능)
 
 - (상위) 일반함수       (하위) throws함수재정의    (O 가능)
   (상위) throws함수    (하위) 일반함수재정의       (X 불가능)
 
 - (상위) throws함수    (하위) rethrows함수재정의  (O 가능)
   (상위) rethrows함수  (하위) throws함수재정의    (X 불가능)

 - Throwing메서드와 Rethrowing메서드를 비교하면 Rethrowing메서드의 범위가 더 작음
 */
```